#VRML_SIM R2020b utf8
WorldInfo {
  coordinateSystem "NUE"
}
Viewpoint {
  orientation -0.9999774815207564 -0.0063013295966424555 0.0023086135926003127 1.1881351750377747
  position -0.14410764986058308 2.0198191941469523 0.8391693075593684
}
TexturedBackground {
  texture "factory"
}
TexturedBackgroundLight {
}
DEF area RectangleArena {
  floorSize 1.016 1.016
  floorTileSize 0.508 0.508
  wallAppearance BrushedAluminium {
    colorOverride 0.4 0.4 0.4
  }
}
DEF epuck E-puck {
  hidden position_0_0 -6.08798414382513e-08
  hidden position_0_1 6.087165364547524e-08
  hidden rotation_1 1 0 0 5.960464477539063e-08
  hidden rotation_2 -1 0 0 5.960464477539063e-08
  translation 0.36557161410308614 -0.00010131135522013779 0.3920661102447097
  rotation -0.04240609067795819 -0.9990997292697947 0.001206004326555192 0.0037932084622748726
  controller "motionEstimation"
  supervisor TRUE
  camera_width 50
  turretSlot [
    InertialUnit {
      rotation 0 1 0 3.14
    }
    DEF righthinge HingeJoint {
      jointParameters HingeJointParameters {
        position 4.1526686857754006e-08
        axis -1 0 0
        anchor 0 0.025 0
      }
      device [
        RotationalMotor {
          name "right wheel motor"
          consumptionFactor 70
          controlPID 8 2 0.5
        }
        PositionSensor {
          name "right wheel sensor"
        }
      ]
      endPoint Solid {
        translation 0.04500995778380096 0.02501338075785909 -2.4671930407728737e-05
        rotation 0.9999993203500066 0.0010052733953939048 -0.0005905293603570316 4.636837080528011
        children [
          DEF WHEEL Transform {
            translation -0.007 0.01 -0.05
            rotation 0 0 1 1.57
            children [
              Shape {
                appearance PBRAppearance {
                  baseColor 0 0 0
                  transparency 1
                  roughness 1
                  metalness 0
                }
                geometry Cylinder {
                  height 0.01
                  radius 0.02
                }
              }
            ]
            rotationStep 0.25
          }
        ]
        name "right wheel(1)"
        boundingObject USE WHEEL
        physics DEF PHYSICS_WHEEL Physics {
          density -1
          mass 0.05
        }
        rotationStep 0.25
        linearVelocity 1.418773253960271e-07 -1.2901059115205018e-07 4.378048886217084e-08
        angularVelocity -1.9899182266841583e-06 6.507417238619698e-07 -8.049740522035893e-06
      }
    }
    DEF lefthinge HingeJoint {
      jointParameters HingeJointParameters {
        position 2.9898276523747804e-08
        axis -1 0 0
        anchor 0 0.025 0
      }
      device [
        RotationalMotor {
          name "left wheel motor"
          consumptionFactor 70
          controlPID 8 0 0
        }
        PositionSensor {
          name "left wheel sensor"
        }
      ]
      endPoint Solid {
        translation -0.04501012942703836 0.0249776719759117 -4.5733975494465604e-05
        rotation -0.9999982113395917 0.00047275264888792994 -0.0018313444653098435 1.2425810501871826
        children [
          DEF WHEEL Transform {
            translation 0.007 0 -0.05
            rotation 0 0 1 1.57
            children [
              Shape {
                appearance PBRAppearance {
                  baseColor 0.1 0.1 0.1
                  transparency 1
                  roughness 1
                  metalness 0
                }
                geometry Cylinder {
                  height 0.01
                  radius 0.02
                }
              }
            ]
            rotationStep 0.25
          }
        ]
        name "left wheel(1)"
        boundingObject USE WHEEL
        physics DEF PHYSICS_WHEEL Physics {
          density -1
          mass 0.05
        }
        linearVelocity 2.5168378760768543e-07 4.933779380787777e-07 1.6569410935775503e-09
        angularVelocity -3.0629075989434945e-07 6.507493875066192e-07 -8.043354248591936e-06
      }
    }
    DEF front_ds DistanceSensor {
      translation 0 0 -0.045
      rotation 0 1 0 1.5708
      name "front_ds"
      recognitionColors [
        0 0 0
      ]
      lookupTable [
        0 0 0
        1.27 1.27 0
      ]
    }
    DEF right_ds DistanceSensor {
      translation 0.035 -0.01 -0.01
      name "right_ds"
      lookupTable [
        0 0 0
        1.27 1.27 0
      ]
    }
    DEF left_ds DistanceSensor {
      translation -0.035 -0.01 -0.01
      rotation 0 1 0 3.14159
      name "left_ds"
      lookupTable [
        0 0 0
        1.27 1.27 0
      ]
    }
    Camera {
      translation 0 -0.01 -0.045
      name "camera1"
      recognitionColors [
        1 1 0
      ]
      fieldOfView 1.57
      width 80
      height 80
      recognition Recognition {
      }
    }
  ]
}
