#VRML_SIM R2020b utf8
WorldInfo {
  coordinateSystem "NUE"
}
Viewpoint {
  orientation 0.005965318230599352 -0.9860138342306054 -0.16655669810688525 3.2487886452123163
  position 0.08322179300041185 0.5269707556426464 -1.5078356859715605
}
TexturedBackground {
}
TexturedBackgroundLight {
}
RectangleArena {
  translation 0 0 0.01
}
Robot {
  translation 1.3595418628905517e-10 -0.0002203618749011954 2.174349179075711e-13
  rotation 3.902229721027397e-06 0.9999999999923863 3.217953687618392e-09 3.1400000000268182
  children [
    DEF Body Transform {
      translation 0 0.0415 0
      children [
        Shape {
          appearance PBRAppearance {
            baseColor 0 0 1
            roughness 1
            metalness 0
          }
          geometry Cylinder {
            height 0.08
            radius 0.045
          }
        }
      ]
    }
    HingeJoint {
      jointParameters HingeJointParameters {
        position -3.135509247532468e-10
        anchor 0.045 0.025 0
      }
      device [
        RotationalMotor {
          name "motor_1"
        }
      ]
      endPoint Solid {
        translation 0.045 0.025 0
        rotation -1.569003566130097e-10 1.567754623766234e-10 1 1.57
        children [
          DEF Wheel Shape {
            appearance PBRAppearance {
              baseColor 1 0 0
              roughness 1
              metalness 0
            }
            geometry Cylinder {
              height 0.01
              radius 0.025
            }
          }
        ]
        boundingObject USE Wheel
        physics DEF wheel_physics Physics {
        }
      }
    }
    HingeJoint {
      jointParameters HingeJointParameters {
        position 3.132710256131929e-10
        anchor -0.045 0.025 0
      }
      device [
        RotationalMotor {
          name "motor_2"
        }
      ]
      endPoint Solid {
        translation -0.045 0.025 0
        rotation 1.5676029555299307e-10 -1.5663551280659644e-10 1 1.57
        children [
          USE Wheel
        ]
        name "solid(1)"
        boundingObject USE Wheel
        physics USE wheel_physics
      }
    }
    Solid {
      translation 0.015 0.07 0.045
      children [
        DEF eyes Shape {
          appearance PBRAppearance {
            baseColor 1 0 0
            roughness 1
            metalness 0
          }
          geometry Box {
            size 0.005 0.005 0.005
          }
        }
      ]
      name "solid(2)"
    }
    Solid {
      translation -0.015 0.07 0.045
      children [
        USE eyes
      ]
      name "solid(3)"
    }
  ]
  boundingObject USE Body
  physics Physics {
  }
  controller "<extern>"
}
